<mujoco model="iiwa14">
  <!-- <compiler angle="radian" autolimits="true"/> -->

  <!-- <option integrator="implicitfast"/> -->

  <!-- <default>
    <default class="iiwa">
      <default class="visual">
        <geom type="mesh" contype="0" conaffinity="0" group="1" material="gray"/>
      </default>
      <default class="collision">
        <geom contype="0"/>
      </default>
    </default>
  </default> -->

  <asset>
    <material name="gray" rgba="0.4 0.4 0.4 1"/>
    <material name="light_gray" rgba="0.6 0.6 0.6 1"/>
    <material name="black" rgba="0 0 0 1"/>
    <material name="orange" rgba="1 0.423529 0.0392157 1"/>

    <mesh name="link_0" file="meshes/link_0.obj"/>
    <mesh name="link_1" file="meshes/link_1.obj"/>
    <mesh name="link_2_orange" file="meshes/link_2_orange.obj"/>
    <mesh name="link_2_gray" file="meshes/link_2_gray.obj"/>
    <mesh name="link_3" file="meshes/link_3.obj"/>
    <mesh name="band" file="meshes/band.obj"/>
    <mesh name="kuka" file="meshes/kuka.obj"/>
    <mesh name="link_4_orange" file="meshes/link_4_orange.obj"/>
    <mesh name="link_4_gray" file="meshes/link_4_gray.obj"/>
    <mesh name="link_5" file="meshes/link_5.obj"/>
    <mesh name="link_6_orange" file="meshes/link_6_orange.obj"/>
    <mesh name="link_6_gray" file="meshes/link_6_gray.obj"/>
    <mesh name="link_7" file="meshes/link_7.obj"/>
  </asset>

  <worldbody>
    <body name="base">
      <!-- robot view -->
      <camera mode="fixed" name="robotview" pos="1.0 0 0.4" quat="0.653 0.271 0.271 0.653"/>
      <inertial mass="5" pos="-0.1 0 0.07" diaginertia="0.05 0.06 0.03"/>
      <!-- mount attached here -->
      <geom type="mesh" contype="0" conaffinity="0" group="1" material="gray" name="link_0_visual" mesh="link_0"/>
      <geom type="mesh" rgba="0.4 0.4 0.4 1" contype="0" name="link_0_collision" mesh="link_0"/>
      <body name="link_1" pos="0 0 0.1575">
        <inertial mass="5.76" pos="0 -0.03 0.12" diaginertia="0.0333 0.033 0.0123"/>
        <joint name="joint_1" pos="0 0 0" axis="0 0 1" limited="true" range="-2.96706 2.96706" damping="0.2415" frictionloss="0.31909"/>
        <geom type="mesh" contype="0" conaffinity="0" group="1" material="gray" name="link_1_visual" mesh="link_1"/>
        <geom type="mesh" rgba="0.4 0.4 0.4 1" contype="0" name="link_1_collision" mesh="link_1"/>
        <body name="link_2" pos="0 0 0.2025" quat="0 0 1 1">
          <inertial mass="6.35" pos="0.0003 0.059 0.042" diaginertia="0.0305 0.0304 0.011" quat="0 0 1 1"/>
          <joint name="joint_2" pos="0 0 0" axis="0 0 1" limited="true" range="-2.0944 2.0944" damping="0.37328" frictionloss="0.1813"/>
          <geom type="mesh" contype="0" conaffinity="0" group="1" material="orange" name="link_2_orange_visual" mesh="link_2_orange"/>
          <geom type="mesh" contype="0" conaffinity="0" group="1" material="gray" name="link_2_gray_visual" mesh="link_2_gray"/>
          <geom type="mesh" rgba="0.4 0.4 0.4 1" contype="0" name="link_2_orange_collision" mesh="link_2_orange"/>
          <geom type="mesh" rgba="0.4 0.4 0.4 1" contype="0" name="link_2_gray_collision" mesh="link_2_gray"/>
          <body name="link_3" pos="0 0.2045 0" quat="0 0 1 1">
            <inertial mass="3.5" pos="0 0.03 0.13" diaginertia="0.025 0.0238 0.0076"/>
            <joint name="joint_3" pos="0 0 0" axis="0 0 1" limited="true" range="-2.96706 2.96706" damping="0.11025" frictionloss="0.07302"/>
            <geom type="mesh" contype="0" conaffinity="0" group="1" material="gray" name="link_3_visual" mesh="link_3"/>
            <geom type="mesh" contype="0" conaffinity="0" group="1" material="light_gray" name="link_3_band_visual" mesh="band"/>
            <geom type="mesh" contype="0" conaffinity="0" group="1" material="black" name="link_3_logo_visual" mesh="kuka"/>
            <geom type="mesh" rgba="0.4 0.4 0.4 1" contype="0" name="link_3_collision" mesh="link_3"/>
            <geom type="mesh" rgba="0.4 0.4 0.4 1" contype="0" name="link_3_band_collision" mesh="band"/>
            <geom type="mesh" rgba="0.4 0.4 0.4 1" contype="0" name="link_3_logo_collision" mesh="kuka"/>
            <body name="link_4" pos="0 0 0.2155" quat="1 1 0 0">
              <inertial mass="3.5" pos="0 0.067 0.034" diaginertia="0.017 0.0164 0.006" quat="1 1 0 0"/>
              <joint name="joint_4" pos="0 0 0" axis="0 0 1" limited="true" range="-2.0944 2.0944" damping="0.1" frictionloss="0.17671"/>
              <geom type="mesh" contype="0" conaffinity="0" group="1" material="orange" name="link_4_orange_visual" mesh="link_4_orange"/>
              <geom type="mesh" contype="0" conaffinity="0" group="1" material="gray" name="link_4_gray_visual" mesh="link_4_gray"/>
              <geom type="mesh" rgba="0.4 0.4 0.4 1" contype="0" name="link_4_orange_collision" mesh="link_4_orange"/>
              <geom type="mesh" rgba="0.4 0.4 0.4 1" contype="0" name="link_4_gray_collision" mesh="link_4_gray"/>
              <body name="link_5" pos="0 0.1845 0" quat="0 0 1 1">
                <inertial mass="3.5" pos="0.0001 0.021 0.076" diaginertia="0.01 0.0087 0.00449"/>
                <joint name="joint_5" pos="0 0 0" axis="0 0 1" limited="true" range="-2.96706 2.96706" damping="0.1" frictionloss="0.03463"/>
                <geom type="mesh" contype="0" conaffinity="0" group="1" material="gray" name="link_5_visual" mesh="link_5"/>
                <geom type="mesh" contype="0" conaffinity="0" group="1" material="light_gray" name="link_5_band_visual" mesh="band"/>
                <geom type="mesh" contype="0" conaffinity="0" group="1" material="black" name="link_5_logo_visual" mesh="kuka"/>
                <geom type="mesh" rgba="0.4 0.4 0.4 1" contype="0" name="link_5_collision" mesh="link_5"/>
                <geom type="mesh" rgba="0.4 0.4 0.4 1" contype="0" name="link_5_band_collision" mesh="band"/>
                <geom type="mesh" rgba="0.4 0.4 0.4 1" contype="0" name="link_5_logo_collision" mesh="kuka"/>
                <body name="link_6" pos="0 0 0.2155" quat="1 1 0 0">
                  <inertial mass="1.8" pos="0 0.0006 0.0004" diaginertia="0.0049 0.0047 0.0036" quat="1 1 0 0"/>
                  <joint name="joint_6" pos="0 0 0" axis="0 0 1" limited="true" range="-2.0944 2.0944" damping="0.12484" frictionloss="0.13391"/>
                  <geom type="mesh" contype="0" conaffinity="0" group="1" material="orange" name="link_6_orange_visual" mesh="link_6_orange"/>
                  <geom type="mesh" contype="0" conaffinity="0" group="1" material="gray" name="link_6_gray_visual" mesh="link_6_gray"/>
                  <geom type="mesh" rgba="0.4 0.4 0.4 1" contype="0" name="link_6_orange_collision" mesh="link_6_orange"/>
                  <geom type="mesh" rgba="0.4 0.4 0.4 1" contype="0" name="link_6_gray_collision" mesh="link_6_gray"/>
                  <body name="link_7" pos="0 0.081 0" quat="0 0 1 1">
                    <inertial mass="1.2" pos="0 0 0.02" diaginertia="0.001 0.001 0.001"/>
                    <joint name="joint_7" pos="0 0 0" axis="0 0 1" limited="true" range="-3.05433 3.05433" damping="0.1" frictionloss="0.0871"/>
                    <geom type="mesh" contype="0" conaffinity="0" group="1" material="gray" name="link_7_visual" mesh="link_7"/>
                    <geom type="mesh" rgba="0.4 0.4 0.4 1" contype="0" name="link_7_collision" mesh="link_7"/>
                    <body name="right_hand" pos="0 0 0.045" quat="0 0 0 1">
                      <!-- This camera points out from the eef. -->
                      <camera mode="fixed" name="eye_in_hand" pos="0.05 0 0" quat="0 0.707108 0.707108 0" fovy="75"/>
                      <!-- To add gripper -->
                    </body>
                  </body>
                </body>
              </body>
            </body>
          </body>
        </body>
      </body>
    </body>
  </worldbody>

  <contact>
    <exclude body1="base" body2="link_1"/>
    <exclude body1="base" body2="link_2"/>
    <exclude body1="base" body2="link_3"/>
    <exclude body1="link_1" body2="link_3"/>
    <exclude body1="link_3" body2="link_5"/>
    <exclude body1="link_4" body2="link_7"/>
    <exclude body1="link_5" body2="link_7"/>
  </contact>

  <actuator>
    <motor ctrllimited="true" name="torq_j1" joint="joint_1" ctrlrange="-320 320"/>
    <motor ctrllimited="true" name="torq_j2" joint="joint_2" ctrlrange="-320 320"/>
    <motor ctrllimited="true" name="torq_j3" joint="joint_3" ctrlrange="-176 176"/>
    <motor ctrllimited="true" name="torq_j4" joint="joint_4" ctrlrange="-176 176"/>
    <motor ctrllimited="true" name="torq_j5" joint="joint_5" ctrlrange="-110 110"/>
    <motor ctrllimited="true" name="torq_j6" joint="joint_6" ctrlrange="-40 40"/>
    <motor ctrllimited="true" name="torq_j7" joint="joint_7" ctrlrange="-40 40"/>
  </actuator>

  <keyframe>
    <key name="home" qpos="0 0 0 -1.5708 0 1.5708 0"/>
  </keyframe>
</mujoco>
