<robot name="iiwa14">
  <!-- KDL requires a link without inertia -->
  <link name="lbr_floating_link"/>
  <!--joint
        between <robot_name>_floating_link and robot_name_link_0-->
  <joint name="lbr_floating_joint" type="fixed">
    <parent link="lbr_floating_link"/>
    <child link="lbr_link_0"/>
  </joint>
  <!-- ros_control-plugin -->
  <gazebo>
    <plugin filename="ign_ros2_control-system" name="ign_ros2_control::IgnitionROS2ControlPlugin">
      <parameters>/home/anselmo/fri-stack/install/lbr_description/share/lbr_description/ros2_control/lbr_controllers.yaml</parameters>
      <ros>
        <namespace>/lbr</namespace>
      </ros>
    </plugin>
  </gazebo>
  <gazebo reference="lbr_link_0">
    <mu1>0.2</mu1>
    <mu2>0.2</mu2>
  </gazebo>
  <gazebo reference="lbr_A1">
    <implicitSpringDamper>true</implicitSpringDamper>
    <provideFeedback>true</provideFeedback>
  </gazebo>
  <gazebo reference="lbr_link_1">
    <mu1>0.2</mu1>
    <mu2>0.2</mu2>
  </gazebo>
  <gazebo reference="lbr_A2">
    <implicitSpringDamper>true</implicitSpringDamper>
    <provideFeedback>true</provideFeedback>
  </gazebo>
  <gazebo reference="lbr_link_2">
    <mu1>0.2</mu1>
    <mu2>0.2</mu2>
  </gazebo>
  <gazebo reference="lbr_A3">
    <implicitSpringDamper>true</implicitSpringDamper>
    <provideFeedback>true</provideFeedback>
  </gazebo>
  <gazebo reference="lbr_link_3">
    <mu1>0.2</mu1>
    <mu2>0.2</mu2>
  </gazebo>
  <gazebo reference="lbr_A4">
    <implicitSpringDamper>true</implicitSpringDamper>
    <provideFeedback>true</provideFeedback>
  </gazebo>
  <gazebo reference="lbr_link_4">
    <mu1>0.2</mu1>
    <mu2>0.2</mu2>
  </gazebo>
  <gazebo reference="lbr_A5">
    <implicitSpringDamper>true</implicitSpringDamper>
    <provideFeedback>true</provideFeedback>
  </gazebo>
  <gazebo reference="lbr_link_5">
    <mu1>0.2</mu1>
    <mu2>0.2</mu2>
  </gazebo>
  <gazebo reference="lbr_A6">
    <implicitSpringDamper>true</implicitSpringDamper>
    <provideFeedback>true</provideFeedback>
  </gazebo>
  <gazebo reference="lbr_link_6">
    <mu1>0.2</mu1>
    <mu2>0.2</mu2>
  </gazebo>
  <gazebo reference="lbr_A7">
    <implicitSpringDamper>true</implicitSpringDamper>
    <provideFeedback>true</provideFeedback>
  </gazebo>
  <gazebo reference="lbr_link_7">
    <mu1>0.2</mu1>
    <mu2>0.2</mu2>
  </gazebo>
  <ros2_control name="lbr_system_interface" type="system">
    <joint name="lbr_A1">
      <command_interface name="position">
        <param name="min">-2.9670597283903604</param>
        <param name="max">2.9670597283903604</param>
      </command_interface>
      <command_interface name="effort">
        <param name="min">-320</param>
        <param name="max"> 320</param>
      </command_interface>
      <state_interface name="position"/>
      <state_interface name="velocity"/>
      <state_interface name="effort"/>
    </joint>
    <joint name="lbr_A2">
      <command_interface name="position">
        <param name="min">-2.0943951023931953</param>
        <param name="max">2.0943951023931953</param>
      </command_interface>
      <command_interface name="effort">
        <param name="min">-320</param>
        <param name="max"> 320</param>
      </command_interface>
      <state_interface name="position"/>
      <state_interface name="velocity"/>
      <state_interface name="effort"/>
    </joint>
    <joint name="lbr_A3">
      <command_interface name="position">
        <param name="min">-2.9670597283903604</param>
        <param name="max">2.9670597283903604</param>
      </command_interface>
      <command_interface name="effort">
        <param name="min">-176</param>
        <param name="max"> 176</param>
      </command_interface>
      <state_interface name="position"/>
      <state_interface name="velocity"/>
      <state_interface name="effort"/>
    </joint>
    <joint name="lbr_A4">
      <command_interface name="position">
        <param name="min">-2.0943951023931953</param>
        <param name="max">2.0943951023931953</param>
      </command_interface>
      <command_interface name="effort">
        <param name="min">-176</param>
        <param name="max"> 176</param>
      </command_interface>
      <state_interface name="position"/>
      <state_interface name="velocity"/>
      <state_interface name="effort"/>
    </joint>
    <joint name="lbr_A5">
      <command_interface name="position">
        <param name="min">-2.9670597283903604</param>
        <param name="max">2.9670597283903604</param>
      </command_interface>
      <command_interface name="effort">
        <param name="min">-110</param>
        <param name="max"> 110</param>
      </command_interface>
      <state_interface name="position"/>
      <state_interface name="velocity"/>
      <state_interface name="effort"/>
    </joint>
    <joint name="lbr_A6">
      <command_interface name="position">
        <param name="min">-2.0943951023931953</param>
        <param name="max">2.0943951023931953</param>
      </command_interface>
      <command_interface name="effort">
        <param name="min">-40</param>
        <param name="max"> 40</param>
      </command_interface>
      <state_interface name="position"/>
      <state_interface name="velocity"/>
      <state_interface name="effort"/>
    </joint>
    <joint name="lbr_A7">
      <command_interface name="position">
        <param name="min">-3.0543261909900763</param>
        <param name="max">3.0543261909900763</param>
      </command_interface>
      <command_interface name="effort">
        <param name="min">-40</param>
        <param name="max"> 40</param>
      </command_interface>
      <state_interface name="position"/>
      <state_interface name="velocity"/>
      <state_interface name="effort"/>
    </joint>
  </ros2_control>
  <link name="lbr_link_0">
    <inertial>
      <origin rpy="0 0 0" xyz="-0.1 0 0.07"/>
      <mass value="5"/>
      <inertia ixx="0.0333" ixy="0.0" ixz="0.0" iyy="0.033" iyz="0.0" izz="0.0123"/>
    </inertial>
    <visual>
      <origin rpy="0 0 0" xyz="0 0 0"/>
      <geometry>
        <mesh filename="package://lbr_description/meshes/iiwa14/mjctrl_mesh/link_0.obj"/>
      </geometry>
    </visual>
  </link>
  <joint name="lbr_A1" type="revolute">
    <origin rpy="0 0 0" xyz="0 0 0.1575"/>
    <parent link="lbr_link_0"/>
    <child link="lbr_link_1"/>
    <axis xyz="0.0 0.0 1.0"/>
    <limit effort="320" lower="-2.9670597283903604" upper="2.9670597283903604" velocity="1.4835298641951802"/>
    <dynamics damping="0.2415" friction="0.31909"/>
  </joint>
  <link name="lbr_link_1">
    <inertial>
      <origin rpy="0 0 0" xyz="0 -0.03 0.12"/>
      <mass value="5.76"/>
      <inertia ixx="0.0333" ixy="0.0" ixz="0.0" iyy="0.033" iyz="0.0" izz="0.0123"/>
    </inertial>
    <visual>
      <origin rpy="0 0 0" xyz="0.0 0.0 0.0"/>
      <geometry>
        <mesh filename="package://lbr_description/meshes/iiwa14/mjctrl_mesh/link_1.obj"/>
      </geometry>
    </visual>
  </link>
  <joint name="lbr_A2" type="revolute">
    <origin rpy="1.5707963267948966 0 3.141592653589793" xyz="0 0 0.2025"/>
    <parent link="lbr_link_1"/>
    <child link="lbr_link_2"/>
    <axis xyz="0.0 0.0 1.0"/>
    <limit effort="320" lower="-2.0943951023931953" upper="2.0943951023931953" velocity="1.4835298641951802"/>
    <dynamics damping="0.37328" friction="0.1813"/>
  </joint>
  <link name="lbr_link_2">
    <inertial>
      <origin rpy="0 0 0" xyz="0.0003 0.059 0.042"/>
      <mass value="6.35"/>
      <inertia ixx="0.0305" ixy="0.0" ixz="0.0" iyy="0.01100" iyz="0.0" izz="0.03040"/>
    </inertial>
    <visual>
      <origin rpy="0 0 0" xyz="0.0 0.0 0.0"/>
      <geometry>
        <mesh filename="package://lbr_description/meshes/iiwa14/mjctrl_mesh/link_2_grey.obj"/>
      </geometry>
    </visual>
    <visual>
      <geometry>
        <mesh filename="package://lbr_description/meshes/iiwa14/mjctrl_mesh/link_2_orange.obj"/>
      </geometry>
    </visual>
  </link>
  <joint name="lbr_A3" type="revolute">
    <origin rpy="1.5707963267948966 0 3.141592653589793" xyz="0 0.2045 0"/>
    <parent link="lbr_link_2"/>
    <child link="lbr_link_3"/>
    <axis xyz="0.0 0.0 1.0"/>
    <limit effort="176" lower="-2.9670597283903604" upper="2.9670597283903604" velocity="1.7453292519943295"/>
    <dynamics damping="0.11025" friction="0.07302"/>
  </joint>
  <link name="lbr_link_3">
    <inertial>
      <origin rpy="0 0 0" xyz="0 0.03 0.13"/>
      <mass value="3.5"/>
      <inertia ixx="0.025" ixy="0.0" ixz="0.0" iyy="0.0238" iyz="0.0" izz="0.0076"/>
    </inertial>
    <visual>
      <origin rpy="0 0 0" xyz="0.0 0.0 0.0"/>
      <geometry>
        <mesh filename="package://lbr_description/meshes/iiwa14/mjctrl_mesh/link_3.obj"/>
      </geometry>
    </visual>
    <visual>
      <geometry>
        <mesh filename="package://lbr_description/meshes/iiwa14/mjctrl_mesh/band.obj"/>
      </geometry>
    </visual>
    <visual>
      <geometry>
        <mesh filename="package://lbr_description/meshes/iiwa14/mjctrl_mesh/kuka.obj"/>
      </geometry>
    </visual>
  </link>
  <joint name="lbr_A4" type="revolute">
    <origin rpy="1.5707963267948966 0 0" xyz="0 0 0.2155"/>
    <parent link="lbr_link_3"/>
    <child link="lbr_link_4"/>
    <axis xyz="0.0 0.0 1.0"/>
    <limit effort="176" lower="-2.0943951023931953" upper="2.0943951023931953" velocity="1.3089969389957472"/>
    <dynamics damping="0.1" friction="0.17671"/>
  </joint>
  <link name="lbr_link_4">
    <inertial>
      <origin rpy="0 0 0" xyz="0 0.067 0.034"/>
      <mass value="3.5"/>
      <inertia ixx="0.017" ixy="0.0" ixz="0.0" iyy="0.00600" iyz="0.0" izz="0.01640"/>
    </inertial>
    <visual>
      <origin rpy="0 0 0" xyz="0.0 0.0 0.0"/>
      <geometry>
        <mesh filename="package://lbr_description/meshes/iiwa14/mjctrl_mesh/link_4_orange.obj"/>
      </geometry>
    </visual>
    <visual>
      <geometry>
        <mesh filename="package://lbr_description/meshes/iiwa14/mjctrl_mesh/link_4_grey.obj"/>
      </geometry>
    </visual>
  </link>
  <joint name="lbr_A5" type="revolute">
    <origin rpy="1.5707963267948966 0 3.141592653589793" xyz="0 0.1845 0"/>
    <parent link="lbr_link_4"/>
    <child link="lbr_link_5"/>
    <axis xyz="0.0 0.0 1.0"/>
    <limit effort="110" lower="-2.9670597283903604" upper="2.9670597283903604" velocity="2.2689280275926285"/>
    <dynamics damping="0.1" friction="0.03463"/>
  </joint>
  <link name="lbr_link_5">
    <inertial>
      <origin rpy="0 0 0" xyz="0.0001 0.021 0.076"/>
      <mass value="3.5"/>
      <inertia ixx="0.01" ixy="0.0" ixz="0.0" iyy="0.0087" iyz="0.0" izz="0.00449"/>
    </inertial>
    <visual>
      <origin rpy="0 0 0" xyz="0.0 0.0 0.0"/>
      <geometry>
        <mesh filename="package://lbr_description/meshes/iiwa14/mjctrl_mesh/link_5.obj"/>
      </geometry>
    </visual>
    <visual>
      <geometry>
        <mesh filename="package://lbr_description/meshes/iiwa14/mjctrl_mesh/band.obj"/>
      </geometry>
    </visual>
    <visual>
      <geometry>
        <mesh filename="package://lbr_description/meshes/iiwa14/mjctrl_mesh/kuka.obj"/>
      </geometry>
    </visual>
  </link>
  <joint name="lbr_A6" type="revolute">
    <origin rpy="1.5707963267948966 0 0" xyz="0 0 0.2155"/>
    <parent link="lbr_link_5"/>
    <child link="lbr_link_6"/>
    <axis xyz="0.0 0.0 1.0"/>
    <limit effort="40" lower="-2.0943951023931953" upper="2.0943951023931953" velocity="2.356194490192345"/>
    <dynamics damping="0.12484" friction="0.13391"/>
  </joint>
  <link name="lbr_link_6">
    <inertial>
      <origin rpy="0 0 0" xyz="0 0.0006 0.0004"/>
      <mass value="1.8"/>
      <inertia ixx="0.0049" ixy="0.0" ixz="0.0" iyy="0.00360" iyz="0.0" izz="0.00470"/>
    </inertial>
    <visual>
      <origin rpy="0 0 0" xyz="0.0 0.0 0.0"/>
      <geometry>
        <mesh filename="package://lbr_description/meshes/iiwa14/mjctrl_mesh/link_6_orange.obj"/>
      </geometry>
    </visual>
    <visual>
      <geometry>
        <mesh filename="package://lbr_description/meshes/iiwa14/mjctrl_mesh/link_6_grey.obj"/>
      </geometry>
    </visual>
  </link>
  <joint name="lbr_A7" type="revolute">
    <origin rpy="1.5707963267948966 0 3.141592653589793" xyz="0 0.081 0"/>
    <parent link="lbr_link_6"/>
    <child link="lbr_link_7"/>
    <axis xyz="0.0 0.0 1.0"/>
    <limit effort="40" lower="-3.0543261909900763" upper="3.0543261909900763" velocity="2.356194490192345"/>
    <dynamics damping="0.1" friction="0.0871"/>
  </joint>
  <link name="lbr_link_7">
    <inertial>
      <origin rpy="0 0 0" xyz="0 0 0.02"/>
      <mass value="1.2"/>
      <inertia ixx="0.001" ixy="0.0" ixz="0.0" iyy="0.001" iyz="0.0" izz="0.001"/>
    </inertial>
    <visual>
      <origin rpy="0 0 0" xyz="0.0 0.0 0.0"/>
      <geometry>
        <mesh filename="package://lbr_description/meshes/iiwa14/mjctrl_mesh/link_7.obj"/>
      </geometry>
    </visual>
  </link>
  <joint name="lbr_joint_ee" type="fixed">
    <parent link="lbr_link_7"/>
    <child link="lbr_link_ee"/>
    <origin rpy="0 0 0" xyz="0 0 0.045"/>
  </joint>
  <link name="lbr_link_ee">
    <inertial>
      <origin rpy="0 0 0" xyz="0.01823 0.00402 0.02330"/>
      <mass value="0.39127"/>
      <inertia ixx="0.00025" ixy="0.00000" ixz="0.00000" iyy="0.00055" iyz="0.00000" izz="0.00062"/>
    </inertial>
    <visual>
      <origin rpy="0 0 0" xyz="0.0 0.0 0.0"/>
      <geometry>
        <mesh filename="package://lbr_description/meshes/eefs/peg_eef_and_camera_assem.stl"/>
      </geometry>
      <material name="custom_color">
        <color rgba="0.5 0.5 0.5 1.0"/>
      </material>
    </visual>
  </link>
  <joint name="lbr_joint_tcp" type="fixed">
    <parent link="lbr_link_ee"/>
    <child link="lbr_link_tcp"/>
    <origin rpy="0 0 0" xyz="0 0 0.0995"/>
  </joint>
  <link name="lbr_link_tcp">
        </link>
</robot>
